Workbook

Sheet Dashboard
A1: WATER TESTING QUALITY DASHBOARD
A2: FILTERS
A3: Record Type: | B3: PQ1-2/OCL
A4: Water Type: | B4: PRW
A5: Location: | B5: AFTER RO SYSTEM NO.12 SV15
A6: Result: | B6: FAILED
A8: METRICS
A9: Total Tests | B9: 908 | C9: Passed | D9: 883
A10: Failed | B10: 25 | C10: Pass Rate | D10: 0.972
A12: Record Type | B12: Passed | C12: Failed
A13: PQ1-2/OCL | B13: 67 | C13: 0
A14: PQ1-2/OLD | B14: 81 | C14: 0
A15: Routine | B15: 735 | C15: 25
A16: Water Type | B16: Passed | C16: Failed
A17: PRW | B17: 73 | C17: 24
A18: PW | B18: 782 | C18: 1
A19: RO water | B19: 28 | C19: 0
A20: Location | B20: Passed | C20: Failed
A21: AFTER RO SYSTEM NO.12 SV14 | B21: 15 | C21: 3
A22: AFTER RO SYSTEM NO.12 SV15 | B22: 8 | C22: 2
A23: ALCOHOL STORAGE | B23: 2 | C23: 0
A24: AUTOCLAVE | B24: 4 | C24: 0
A25: After Cartridge filter 5 µm (B10) | B25: 17 | C25: 12
A26: After Cartridge filter 5 µm (B12) | B26: 1 | C26: 0
A27: After Cartridge filter 5 µm (B16) | B27: 1 | C27: 1
A28: After Chlorine circulation tank (B10) | B28: 25 | C28: 0
A29: After Chlorine circulation tank (B16) | B29: 2 | C29: 0
A30: After EDI (B10) | B30: 24 | C30: 0
A31: After EDI (B12) | B31: 1 | C31: 0
A32: After EDI (B16) | B32: 2 | C32: 0
... A35: After RO (Before EDI) (B12) | B35: 1 | C35: 0
A36: Month | B36: Passed | C36: Failed
A37: 45658 | B37: 62 | C37: 7
A38: 45689 | B38: 73 | C38: 4
A39: 45717 | B39: 52 | C39: 1
A40: 45748 | B40: 71 | C40: 2
A41: 45778 | B41: 42 | C41: 1
A42: 45809 | B42: 71 | C42: 4
A43: 45839 | B43: 61 | C43: 3
A44: 45870 | B44: 58 | C44: 3
...

Sheet prw-pw
A1: samplingDate | B1: samplingPoint | C1: samplingTag | D1: recordStatus | E1: worksheet No. | F1: worksheetCreate | G1: noLocation | H1: building | I1: location | J1: waterType | K1: performedDate | L1: determinedDate | M1: result1 | N1: result2 | O1: resultAvg | P1: qualityEvent | Q1: comment | R1: criteria | S1: statusResult | T1: Exclude | U1: status | V1: syncStatus
A2: 46161 | B2: OSD28 | C2: {=_xlfn.XLOOKUP(B2, DB[samplingPoint], DB[samplingTag])} -> DV116.15 | D2: Speacial | E2: WT-26-0070 | F2: TRUE | G2: {=_xlfn.XLOOKUP($B2, DB[samplingPoint], DB[noLocation])} -> 10-3-104 | H2: Building 10 | I2: {=_xlfn.XLOOKUP($B2, DB[samplingPoint], DB[location])} -> BINDER PREPARATION | J2: {=_xlfn.XLOOKUP($B2, DB[samplingPoint], DB[waterType])} -> PW | K2: =$A2+1 -> 46162 | L2: 46165 | M2: 17 | N2: 7 | O2: =IFERROR(ROUNDUP(AVERAGE($M2:$N2), 0), "") -> 12 | P2: เก็บเพิ่มจาก oos PW-M-2-26-001 | R2: {=_xlfn.XLOOKUP($B2, DB[samplingPoint], DB[Criteria])} -> 100 | S2: =iferror(ifs($O2>R2, "NOT-PASSED", O2<=R2, "PASSED"), "NA") -> PASSED | T2: FALSE | V2: synced
A3: 46164 | B3: GOSD01 | C3: {=_xlfn.XLOOKUP(B3, DB[samplingPoint], DB[samplingTag])} -> VB-05(10) | D3: PQ3-Week3 | E3: WT-26-0071 | F3: TRUE | G3: {=_xlfn.XLOOKUP($B3, DB[samplingPoint], DB[noLocation])} -> WATER SYSTEM (B10) | H3: Building 10 | I3: {=_xlfn.XLOOKUP($B3, DB[samplingPoint], DB[location])} -> After Chlorine circulation tank (B10) | J3: {=_xlfn.XLOOKUP($B3, DB[samplingPoint], DB[waterType])} -> PRW | K3: =$A3+1 -> 46165 | L3: 46173 | M3: 0 | N3: 0 | O3: =IFERROR(ROUNDUP(AVERAGE($M3:$N3), 0), "") -> 0 | R3: {=_xlfn.XLOOKUP($B3, DB[samplingPoint], DB[Criteria])} -> 500 | S3: =iferror(ifs($O3>R3, "NOT-PASSED", O3<=R3, "PASSED"), "NA") -> PASSED | V3: synced
A4: 46164 | B4: GOSD03 | C4: {=_xlfn.XLOOKUP(B4, DB[samplingPoint], DB[samplingTag])} -> V50-61(10) | D4: PQ3-Week3 | E4: WT-26-0071 | F4: TRUE | G4: {=_xlfn.XLOOKUP($B4, DB[samplingPoint], DB[noLocation])} -> WATER SYSTEM (B10) | H4: Building 10 | I4: {=_xlfn.XLOOKUP($B4, DB[samplingPoint], DB[location])} -> After Cartridge filter 5 µm (B10) | J4: {=_xlfn.XLOOKUP($B4, DB[samplingPoint], DB[waterType])} -> PRW | K4: =$A4+1 -> 46165 | L4: 46173 | M4: 0 | N4: 0 | O4: =IFERROR(ROUNDUP(AVERAGE($M4:$N4), 0), "") -> 0 | R4: {=_xlfn.XLOOKUP($B4, DB[samplingPoint], DB[Criteria])} -> 500 | S4: =iferror(ifs($O4>R4, "NOT-PASSED", O4<=R4, "PASSED"), "NA") -> PASSED | V4: synced
A5: 46164 | B5: GOSD04 | C5: {=_xlfn.XLOOKUP(B5, DB[samplingPoint], DB[samplingTag])} -> V50-11C(10) | D5: PQ3-Week3 | E5: WT-26-0071 | F5: TRUE | G5: {=_xlfn.XLOOKUP($B5, DB[samplingPoint], DB[noLocation])} -> WATER SYSTEM (B10) | H5: Building 10 | I5: {=_xlfn.XLOOKUP($B5, DB[samplingPoint], DB[location])} -> After RO (Before EDI) (B10) | J5: {=_xlfn.XLOOKUP($B5, DB[samplingPoint], DB[waterType])} -> RO water | K5: =$A5+1 -> 46165 | L5: 46173 | M5: 0 | N5: 0 | O5: =IFERROR(ROUNDUP(AVERAGE($M5:$N5), 0), "") -> 0 | R5: {=_xlfn.XLOOKUP($B5, DB[samplingPoint], DB[Criteria])} -> 500 | S5: =iferror(ifs($O5>R5, "NOT-PASSED", O5<=R5, "PASSED"), "NA") -> PASSED | V5: synced
A6: 46164 | B6: GOSD05 | C6: {=_xlfn.XLOOKUP(B6, DB[samplingPoint], DB[samplingTag])} -> V50-39(10) | D6: PQ3-Week3 | E6: WT-26-0071 | F6: TRUE | G6: {=_xlfn.XLOOKUP($B6, DB[samplingPoint], DB[noLocation])} -> WATER SYSTEM (B10) | H6: Building 10 | I6: {=_xlfn.XLOOKUP($B6, DB[samplingPoint], DB[location])} -> After EDI (B10) | J6: {=_xlfn.XLOOKUP($B6, DB[samplingPoint], DB[waterType])} -> PW | K6: =$A6+1 -> 46165 | L6: 46173 | M6: 0 | N6: 0 | O6: =IFERROR(ROUNDUP(AVERAGE($M6:$N6), 0), "") -> 0 | R6: {=_xlfn.XLOOKUP($B6, DB[samplingPoint], DB[Criteria])} -> 100 | S6: =iferror(ifs($O6>R6, "NOT-PASSED", O6<=R6, "PASSED"), "NA") -> PASSED | V6: synced
A7: 46164 | B7: GOSD06 | C7: {=_xlfn.XLOOKUP(B7, DB[samplingPoint], DB[samplingTag])} -> SV113.01 | D7: PQ3-Week3 | E7: WT-26-0071 | F7: TRUE | G7: {=_xlfn.XLOOKUP($B7, DB[samplingPoint], DB[noLocation])} -> WATER SYSTEM (B10) | H7: Building 10 | I7: {=_xlfn.XLOOKUP($B7, DB[samplingPoint], DB[location])} -> After Storage tank (B10) | J7: {=_xlfn.XLOOKUP($B7, DB[samplingPoint], DB[waterType])} -> PW | K7: =$A7+1 -> 46165 | L7: 46173 | M7: 0 | N7: 0 | O7: =IFERROR(ROUNDUP(AVERAGE($M7:$N7), 0), "") -> 0 | R7: {=_xlfn.XLOOKUP($B7, DB[samplingPoint], DB[Criteria])} -> 100 | S7: =iferror(ifs($O7>R7, "NOT-PASSED", O7<=R7, "PASSED"), "NA") -> PASSED | V7: synced
A8: 46164 | B8: GOSD07 | C8: {=_xlfn.XLOOKUP(B8, DB[samplingPoint], DB[samplingTag])} -> SV115.02 | D8: PQ3-Week3 | E8: WT-26-0071 | F8: TRUE | G8: {=_xlfn.XLOOKUP($B8, DB[samplingPoint], DB[noLocation])} -> WATER SYSTEM (B10) | H8: Building 10 | I8: {=_xlfn.XLOOKUP($B8, DB[samplingPoint], DB[location])} -> After UV (B10) | J8: {=_xlfn.XLOOKUP($B8, DB[samplingPoint], DB[waterType])} -> PW | K8: =$A8+1 -> 46165 | L8: 46173 | M8: 0 | N8: 0 | O8: =IFERROR(ROUNDUP(AVERAGE($M8:$N8), 0), "") -> 0 | R8: {=_xlfn.XLOOKUP($B8, DB[samplingPoint], DB[Criteria])} -> 100 | S8: =iferror(ifs($O8>R8, "NOT-PASSED", O8<=R8, "PASSED"), "NA") -> PASSED | V8: synced
A9: 46164 | B9: GOSD08 | C9: {=_xlfn.XLOOKUP(B9, DB[samplingPoint], DB[samplingTag])} -> SV117.01 | D9: PQ3-Week3 | E9: WT-26-0071 | F9: TRUE | G9: {=_xlfn.XLOOKUP($B9, DB[samplingPoint], DB[noLocation])} -> WATER SYSTEM (B10) | H9: Building 10 | I9: {=_xlfn.XLOOKUP($B9, DB[samplingPoint], DB[location])} -> Return loop (B10) | J9: {=_xlfn.XLOOKUP($B9, DB[samplingPoint], DB[waterType])} -> PW | K9: =$A9+1 -> 46165 | L9: 46173 | M9: 0 | N9: 0 | O9: =IFERROR(ROUNDUP(AVERAGE($M9:$N9), 0), "") -> 0 | R9: {=_xlfn.XLOOKUP($B9, DB[samplingPoint], DB[Criteria])} -> 100 | S9: =iferror(ifs($O9>R9, "NOT-PASSED", O9<=R9, "PASSED"), "NA") -> PASSED | V9: synced
A10: 46164 | B10: OSD13 | C10: {=_xlfn.XLOOKUP(B10, DB[samplingPoint], DB[samplingTag])} -> DV116.25 | D10: PQ3-Week3 | E10: WT-26-0071 | F10: TRUE | G10: {=_xlfn.XLOOKUP($B10, DB[samplingPoint], DB[noLocation])} -> 10-3-171 | H10: Building 10 | I10: {=_xlfn.XLOOKUP($B10, DB[samplingPoint], DB[location])} -> TOOL WASHING-P | J10: {=_xlfn.XLOOKUP($B10, DB[samplingPoint], DB[waterType])} -> PW | K10: =$A10+1 -> 46165 | L10: 46173 | M10: 0 | N10: 0 | O10: =IFERROR(ROUNDUP(AVERAGE($M10:$N10), 0), "") -> 0 | R10: {=_xlfn.XLOOKUP($B10, DB[samplingPoint], DB[Criteria])} -> 100 | S10: =iferror(ifs($O10>R10, "NOT-PASSED", O10<=R10, "PASSED"), "NA") -> PASSED | V10: synced
A11: 46164 | B11: OSD14 | C11: {=_xlfn.XLOOKUP(B11, DB[samplingPoint], DB[samplingTag])} -> DV116.24 | D11: PQ3-Week3 | E11: WT-26-0071 | F11: TRUE | G11: {=_xlfn.XLOOKUP($B11, DB[samplingPoint], DB[noLocation])} -> 10-3-163 | H11: Building 10 | I11: {=_xlfn.XLOOKUP($B11, DB[samplingPoint], DB[location])} -> WET GRANULATION 1-P | K11: =$A11+1 -> 46165 | L11: 46173 | M11: 0 | N11: 0 | O11: =IFERROR(ROUNDUP(AVERAGE($M11:$N11), 0), "") -> 0 | R11: {=_xlfn.XLOOKUP($B11, DB[samplingPoint], DB[Criteria])} -> 100 | S11: =iferror(ifs($O11>R11, "NOT-PASSED", O11<=R11, "PASSED"), "NA") -> PASSED | V11: synced
A12: 46164 | B12: OSD15 | C12: {=_xlfn.XLOOKUP(B12, DB[samplingPoint], DB[samplingTag])} -> DV116.23 | D12: PQ3-Week3 | E12: WT-26-0071 | F12: TRUE | G12: {=_xlfn.XLOOKUP($B12, DB[samplingPoint], DB[noLocation])} -> 10-3-159 | H12: Building 10 | I12: {=_xlfn.XLOOKUP($B12, DB[samplingPoint], DB[location])} -> BINDER PREPARATION-P | J12: {=_xlfn.XLOOKUP($B11, DB[samplingPoint], DB[waterType])} -> PW | K12: =$A12+1 -> 46165 | L12: 46173 | M12: 0 | N12: 0 | O12: =IFERROR(ROUNDUP(AVERAGE($M12:$N12), 0), "") -> 0 | R12: {=_xlfn.XLOOKUP($B12, DB[samplingPoint], DB[Criteria])} -> 100 | S12: =iferror(ifs($O12>R12, "NOT-PASSED", O12<=R12, "PASSED"), "NA") -> PASSED | V12: synced
A13: 46164 | B13: OSD16 | C13: {=_xlfn.XLOOKUP(B13, DB[samplingPoint], DB[samplingTag])} -> DV116.21 | D13: PQ3-Week3 | E13: WT-26-0071 | F13: TRUE | G13: {=_xlfn.XLOOKUP($B13, DB[samplingPoint], DB[noLocation])} -> 10-3-152 | H13: Building 10 | I13: {=_xlfn.XLOOKUP($B13, DB[samplingPoint], DB[location])} -> WASHING-P | J13: {=_xlfn.XLOOKUP($B12, DB[samplingPoint], DB[waterType])} -> PW | K13: =$A13+1 -> 46165 | L13: 46173 | M13: 0 | N13: 0 | O13: =IFERROR(ROUNDUP(AVERAGE($M13:$N13), 0), "") -> 0 | R13: {=_xlfn.XLOOKUP($B13, DB[samplingPoint], DB[Criteria])} -> 100 | S13: =iferror(ifs($O13>R13, "NOT-PASSED", O13<=R13, "PASSED"), "NA") -> PASSED | V13: synced
A14: 46164 | B14: OSD17 | C14: {=_xlfn.XLOOKUP(B14, DB[samplingPoint], DB[samplingTag])} -> DV116.22 | D14: PQ3-Week3 | E14: WT-26-0071 | F14: TRUE | G14: {=_xlfn.XLOOKUP($B14, DB[samplingPoint], DB[noLocation])} -> 10-3-152 | H14: Building 10 | I14: {=_xlfn.XLOOKUP($B14, DB[samplingPoint], DB[location])} -> WASHING-P | J14: {=_xlfn.XLOOKUP($B14, DB[samplingPoint], DB[waterType])} -> PW | K14: =$A14+1 -> 46165 | L14: 46173 | M14: 0 | N14: 0 | O14: =IFERROR(ROUNDUP(AVERAGE($M14:$N14), 0), "") -> 0 | R14: {=_xlfn.XLOOKUP($B14, DB[samplingPoint], DB[Criteria])} -> 100 | S14: =iferror(ifs($O14>R14, "NOT-PASSED", O14<=R14, "PASSED"), "NA") -> PASSED | V14: synced
A15: 46164 | B15: OSD18 | C15: {=_xlfn.XLOOKUP(B15, DB[samplingPoint], DB[samplingTag])} -> SV116.13 | D15: PQ3-Week3 | E15: WT-26-0071 | F15: TRUE | G15: {=_xlfn.XLOOKUP($B15, DB[samplingPoint], DB[noLocation])} -> 10-3-152 | H15: Building 10 | I15: {=_xlfn.XLOOKUP($B15, DB[samplingPoint], DB[location])} -> WASHING-P | J15: {=_xlfn.XLOOKUP($B15, DB[samplingPoint], DB[waterType])} -> PW | K15: =$A15+1 -> 46165 | L15: 46173 | M15: 0 | N15: 0 | O15: =IFERROR(ROUNDUP(AVERAGE($M15:$N15), 0), "") -> 0 | R15: {=_xlfn.XLOOKUP($B15, DB[samplingPoint], DB[Criteria])} -> 100 | S15: =iferror(ifs($O15>R15, "NOT-PASSED", O15<=R15, "PASSED"), "NA") -> PASSED | V15: synced
A16: 46164 | B16: OSD19 | C16: {=_xlfn.XLOOKUP(B16, DB[samplingPoint], DB[samplingTag])} -> DV116.20 | D16: PQ3-Week3 | E16: WT-26-0071 | F16: TRUE | G16: {=_xlfn.XLOOKUP($B16, DB[samplingPoint], DB[noLocation])} -> 10-3-149 | H16: Building 10 | I16: {=_xlfn.XLOOKUP($B16, DB[samplingPoint], DB[location])} -> IPQC-1-P | J16: {=_xlfn.XLOOKUP($B16, DB[samplingPoint], DB[waterType])} -> PW | K16: =$A16+1 -> 46165 | L16: 46173 | M16: 0 | N16: 0 | O16: =IFERROR(ROUNDUP(AVERAGE($M16:$N16), 0), "") -> 0 | R16: {=_xlfn.XLOOKUP($B16, DB[samplingPoint], DB[Criteria])} -> 100 | S16: =iferror(ifs($O16>R16, "NOT-PASSED", O16<=R16, "PASSED"), "NA") -> PASSED | V16: synced
A17: 46164 | B17: OSD20 | C17: {=_xlfn.XLOOKUP(B17, DB[samplingPoint], DB[samplingTag])} -> DV116.19 | D17: PQ3-Week3 | E17: WT-26-0071 | F17: TRUE | G17: {=_xlfn.XLOOKUP($B17, DB[samplingPoint], DB[noLocation])} -> 10-3-143 | H17: Building 10 | I17: {=_xlfn.XLOOKUP($B17, DB[samplingPoint], DB[location])} -> COATING SOLUTION PREP.-P | J17: {=_xlfn.XLOOKUP($B17, DB[samplingPoint], DB[waterType])} -> PW | K17: =$A17+1 -> 46165 | L17: 46173 | M17: 0 | N17: 0 | O17: =IFERROR(ROUNDUP(AVERAGE($M17:$N17), 0), "") -> 0 | R17: {=_xlfn.XLOOKUP($B17, DB[samplingPoint], DB[Criteria])} -> 100 | S17: =iferror(ifs($O17>R17, "NOT-PASSED", O17<=R17, "PASSED"), "NA") -> PASSED | V17: synced
A18: 46164 | B18: OSD21 | C18: {=_xlfn.XLOOKUP(B18, DB[samplingPoint], DB[samplingTag])} -> SV116.12 | D18: PQ3-Week3 | E18: WT-26-0071 | F18: TRUE | G18: {=_xlfn.XLOOKUP($B18, DB[samplingPoint], DB[noLocation])} -> 10-3-144 | H18: Building 10 | I18: {=_xlfn.XLOOKUP($B18, DB[samplingPoint], DB[location])} -> COATING-P | J18: {=_xlfn.XLOOKUP($B18, DB[samplingPoint], DB[waterType])} -> PW | K18: =$A18+1 -> 46165 | L18: 46173 | M18: 0 | N18: 0 | O18: =IFERROR(ROUNDUP(AVERAGE($M18:$N18), 0), "") -> 0 | R18: {=_xlfn.XLOOKUP($B18, DB[samplingPoint], DB[Criteria])} -> 100 | S18: =iferror(ifs($O18>R18, "NOT-PASSED", O18<=R18, "PASSED"), "NA") -> PASSED | V18: synced
A19: 46164 | B19: OSD41 | C19: {=_xlfn.XLOOKUP(B19, DB[samplingPoint], DB[samplingTag])} -> DV116.02 | D19: PQ3-Week3 | E19: WT-26-0071 | F19: TRUE | G19: {=_xlfn.XLOOKUP($B19, DB[samplingPoint], DB[noLocation])} -> 10-1-115 | H19: Building 10 | I19: {=_xlfn.XLOOKUP($B19, DB[samplingPoint], DB[location])} -> WASHING | J19: {=_xlfn.XLOOKUP($B19, DB[samplingPoint], DB[waterType])} -> PW | K19: =$A19+1 -> 46165 | L19: 46173 | M19: 0 | N19: 0 | O19: =IFERROR(ROUNDUP(AVERAGE($M19:$N19), 0), "") -> 0 | R19: {=_xlfn.XLOOKUP($B19, DB[samplingPoint], DB[Criteria])} -> 100 | S19: =iferror(ifs($O19>R19, "NOT-PASSED", O19<=R19, "PASSED"), "NA") -> PASSED | V19: synced
A20: 46164 | B20: OSD42 | C20: {=_xlfn.XLOOKUP(B20, DB[samplingPoint], DB[samplingTag])} -> DV116.01 | D20: PQ3-Week3 | E20: WT-26-0071 | F20: TRUE | G20: {=_xlfn.XLOOKUP($B20, DB[samplingPoint], DB[noLocation])} -> 10-1-057 | H20: Building 10 | I20: {=_xlfn.XLOOKUP($B20, DB[samplingPoint], DB[location])} -> WASHING-P | J20: {=_xlfn.XLOOKUP($B20, DB[samplingPoint], DB[waterType])} -> PW | K20: =$A20+1 -> 46165 | L20: 46173 | M20: 0 | N20: 0 | O20: =IFERROR(ROUNDUP(AVERAGE($M20:$N20), 0), "") -> 0 | R20: {=_xlfn.XLOOKUP($B20, DB[samplingPoint], DB[Criteria])} -> 100 | S20: =iferror(ifs($O20>R20, "NOT-PASSED", O20<=R20, "PASSED"), "NA") -> PASSED | V20: synced
A21: 46164 | B21: BU19-14 | C21: {=_xlfn.XLOOKUP(B21, DB[samplingPoint], DB[samplingTag])} -> SV-14 | D21: PQ3-Week3 | E21: WT-26-0072 | F21: TRUE | G21: {=_xlfn.XLOOKUP($B21, DB[samplingPoint], DB[noLocation])} -> PROCESS WATER (B19) | H21: Building 19 | I21: {=_xlfn.XLOOKUP($B21, DB[samplingPoint], DB[location])} -> AFTER RO SYSTEM NO.12 SV14 | J21: {=_xlfn.XLOOKUP($B21, DB[samplingPoint], DB[waterType])} -> PRW | K21: =$A21+1 -> 46165 | L21: 46173 | M21: 0 | N21: 0 | O21: =IFERROR(ROUNDUP(AVERAGE($M21:$N21), 0), "") -> 0 | R21: {=_xlfn.XLOOKUP($B21, DB[samplingPoint], DB[Criteria])} -> 500 | S21: =iferror(ifs($O21>R21, "NOT-PASSED", O21<=R21, "PASSED"), "NA") -> PASSED | V21: synced
A22: 46168 | B22: GOLD05 | C22: {=_xlfn.XLOOKUP(B22, DB[samplingPoint], DB[samplingTag])} -> SV133.01 | D22: PQ3-Week4 | E22: WT-26-0073 | F22: TRUE | G22: {=_xlfn.XLOOKUP($B22, DB[samplingPoint], DB[noLocation])} -> WATER SYSTEM (B12) | H22: Building 12 | I22: {=_xlfn.XLOOKUP($B22, DB[samplingPoint], DB[location])} -> After Storage tank (B12) | J22: {=_xlfn.XLOOKUP($B22, DB[samplingPoint], DB[waterType])} -> PW | K22: =$A22+0 -> 46168 | L22: 46171 | M22: 0 | N22: 0 | O22: =IFERROR(ROUNDUP(AVERAGE($M22:$N22), 0), "") -> 0 | R22: {=_xlfn.XLOOKUP($B22, DB[samplingPoint], DB[Criteria])} -> 100 | S22: =iferror(ifs($O22>R22, "NOT-PASSED", O22<=R22, "PASSED"), "NA") -> PASSED | T22: FALSE | V22: synced
A23: 46168 | B23: GOLD06 | C23: {=_xlfn.XLOOKUP(B23, DB[samplingPoint], DB[samplingTag])} -> SV135.02 | D23: PQ3-Week4 | E23: WT-26-0073 | F23: TRUE | G23: {=_xlfn.XLOOKUP($B23, DB[samplingPoint], DB[noLocation])} -> WATER SYSTEM (B12) | H23: Building 12 | I23: {=_xlfn.XLOOKUP($B23, DB[samplingPoint], DB[location])} -> After UV (B12) | J23: {=_xlfn.XLOOKUP($B23, DB[samplingPoint], DB[waterType])} -> PW | K23: =$A23+0 -> 46168 | L23: 46171 | M23: 0 | N23: 0 | O23: =IFERROR(ROUNDUP(AVERAGE($M23:$N23), 0), "") -> 0 | R23: {=_xlfn.XLOOKUP($B23, DB[samplingPoint], DB[Criteria])} -> 100 | S23: =iferror(ifs($O23>R23, "NOT-PASSED", O23<=R23, "PASSED"), "NA") -> PASSED | T23: FALSE | V23: synced
A24: 46168 | B24: GOLD07 | C24: {=_xlfn.XLOOKUP(B24, DB[samplingPoint], DB[samplingTag])} -> SV137.01 | D24: PQ3-Week4 | E24: WT-26-0073 | F24: TRUE | G24: {=_xlfn.XLOOKUP($B24, DB[samplingPoint], DB[noLocation])} -> WATER SYSTEM (B12) | H24: Building 12 | I24: {=_xlfn.XLOOKUP($B24, DB[samplingPoint], DB[location])} -> Return loop (B12) | J24: {=_xlfn.XLOOKUP($B24, DB[samplingPoint], DB[waterType])} -> PW | K24: =$A24+0 -> 46168 | L24: 46171 | M24: 0 | N24: 0 | O24: =IFERROR(ROUNDUP(AVERAGE($M24:$N24), 0), "") -> 0 | R24: {=_xlfn.XLOOKUP($B24, DB[samplingPoint], DB[Criteria])} -> 100 | S24: =iferror(ifs($O24>R24, "NOT-PASSED", O24<=R24, "PASSED"), "NA") -> PASSED | T24: FALSE | V24: synced
A25: 46168 | B25: OLD06 | C25: {=_xlfn.XLOOKUP(B25, DB[samplingPoint], DB[samplingTag])} -> SV136.09 | D25: PQ3-Week4 | E25: WT-26-0073 | F25: TRUE | G25: {=_xlfn.XLOOKUP($B25, DB[samplingPoint], DB[noLocation])} -> 12-2-039 | H25: Building 12 | I25: {=_xlfn.XLOOKUP($B25, DB[samplingPoint], DB[location])} -> MFG 1 | J25: {=_xlfn.XLOOKUP($B25, DB[samplingPoint], DB[waterType])} -> PW | K25: =$A25+0 -> 46168 | L25: 46171 | M25: 0 | N25: 0 | O25: =IFERROR(ROUNDUP(AVERAGE($M25:$N25), 0), "") -> 0 | R25: {=_xlfn.XLOOKUP($B25, DB[samplingPoint], DB[Criteria])} -> 100 | S25: =iferror(ifs($O25>R25, "NOT-PASSED", O25<=R25, "PASSED"), "NA") -> PASSED | T25: FALSE | V25: synced
A26: 46168 | B26: OLD07 | C26: {=_xlfn.XLOOKUP(B26, DB[samplingPoint], DB[samplingTag])} -> SV136.10 | D26: PQ3-Week4 | E26: WT-26-0073 | F26: TRUE | G26: {=_xlfn.XLOOKUP($B26, DB[samplingPoint], DB[noLocation])} -> 12-2-041 | H26: Building 12 | I26: {=_xlfn.XLOOKUP($B26, DB[samplingPoint], DB[location])} -> MFG 2 | J26: {=_xlfn.XLOOKUP($B26, DB[samplingPoint], DB[waterType])} -> PW | K26: =$A26+0 -> 46168 | L26: 46171 | M26: 0 | N26: 0 | O26: =IFERROR(ROUNDUP(AVERAGE($M26:$N26), 0), "") -> 0 | R26: {=_xlfn.XLOOKUP($B26, DB[samplingPoint], DB[Criteria])} -> 100 | S26: =iferror(ifs($O26>R26, "NOT-PASSED", O26<=R26, "PASSED"), "NA") -> PASSED | T26: FALSE | V26: synced
A27: 46168 | B27: OLD08 | C27: {=_xlfn.XLOOKUP(B27, DB[samplingPoint], DB[samplingTag])} -> SV136.11 | D27: PQ3-Week4 | E27: WT-26-0073 | F27: TRUE | G27: {=_xlfn.XLOOKUP($B27, DB[samplingPoint], DB[noLocation])} -> 12-2-043 | H27: Building 12 | I27: {=_xlfn.XLOOKUP($B27, DB[samplingPoint], DB[location])} -> MFG 3 | J27: {=_xlfn.XLOOKUP($B27, DB[samplingPoint], DB[waterType])} -> PW | K27: =$A27+0 -> 46168 | L27: 46171 | M27: 0 | N27: 0 | O27: =IFERROR(ROUNDUP(AVERAGE($M27:$N27), 0), "") -> 0 | R27: {=_xlfn.XLOOKUP($B27, DB[samplingPoint], DB[Criteria])} -> 100 | S27: =iferror(ifs($O27>R27, "NOT-PASSED", O27<=R27, "PASSED"), "NA") -> PASSED | T27: FALSE | V27: synced
A28: 46168 | B28: OLD09 | C28: {=_xlfn.XLOOKUP(B28, DB[samplingPoint], DB[samplingTag])} -> SV136.13 | D28: PQ3-Week4 | E28: WT-26-0073 | F28: TRUE | G28: {=_xlfn.XLOOKUP($B28, DB[samplingPoint], DB[noLocation])} -> 12-2-043 | H28: Building 12 | I28: {=_xlfn.XLOOKUP($B28, DB[samplingPoint], DB[location])} -> MFG 3 | J28: {=_xlfn.XLOOKUP($B28, DB[samplingPoint], DB[waterType])} -> PW | K28: =$A28+0 -> 46168 | L28: 46171 | M28: 0 | N28: 0 | O28: =IFERROR(ROUNDUP(AVERAGE($M28:$N28), 0), "") -> 0 | R28: {=_xlfn.XLOOKUP($B28, DB[samplingPoint], DB[Criteria])} -> 100 | S28: =iferror(ifs($O28>R28, "NOT-PASSED", O28<=R28, "PASSED"), "NA") -> PASSED | T28: FALSE | V28: synced
A29: 46168 | B29: OLD11 | C29: {=_xlfn.XLOOKUP(B29, DB[samplingPoint], DB[samplingTag])} -> SV136.08 | D29: PQ3-Week4 | E29: WT-26-0073 | F29: TRUE | G29: {=_xlfn.XLOOKUP($B29, DB[samplingPoint], DB[noLocation])} -> 12-2-043 | H29: Building 12 | I29: {=_xlfn.XLOOKUP($B29, DB[samplingPoint], DB[location])} -> MFG 3 | J29: {=_xlfn.XLOOKUP($B29, DB[samplingPoint], DB[waterType])} -> PW | K29: =$A29+0 -> 46168 | L29: 46171 | M29: 0 | N29: 0 | O29: =IFERROR(ROUNDUP(AVERAGE($M29:$N29), 0), "") -> 0 | R29: {=_xlfn.XLOOKUP($B29, DB[samplingPoint], DB[Criteria])} -> 100 | S29: =iferror(ifs($O29>R29, "NOT-PASSED", O29<=R29, "PASSED"), "NA") -> PASSED | T29: FALSE | V29: synced
A30: 46168 | B30: OLD16 | C30: {=_xlfn.XLOOKUP(B30, DB[samplingPoint], DB[samplingTag])} -> SV136.14 | D30: PQ3-Week4 | E30: WT-26-0073 | F30: TRUE | G30: {=_xlfn.XLOOKUP($B30, DB[samplingPoint], DB[noLocation])} -> 12-2-045 | H30: Building 12 | I30: {=_xlfn.XLOOKUP($B30, DB[samplingPoint], DB[location])} -> MFG 4 | J30: {=_xlfn.XLOOKUP($B30, DB[samplingPoint], DB[waterType])} -> PW | K30: =$A30+0 -> 46168 | L30: 46171 | M30: 0 | N30: 0 | O30: =IFERROR(ROUNDUP(AVERAGE($M30:$N30), 0), "") -> 0 | R30: {=_xlfn.XLOOKUP($B30, DB[samplingPoint], DB[Criteria])} -> 100 | S30: =iferror(ifs($O30>R30, "NOT-PASSED", O30<=R30, "PASSED"), "NA") -> PASSED | T30: FALSE | V30: synced
A31: 46168 | B31: OLD18 | C31: {=_xlfn.XLOOKUP(B31, DB[samplingPoint], DB[samplingTag])} -> SV136.02 | D31: PQ3-Week4 | E31: WT-26-0073 | F31: TRUE | G31: {=_xlfn.XLOOKUP($B31, DB[samplingPoint], DB[noLocation])} -> 12-2-024 | H31: Building 12 | I31: {=_xlfn.XLOOKUP($B31, DB[samplingPoint], DB[location])} -> LIQUORICE EXTRACT | J31: {=_xlfn.XLOOKUP($B31, DB[samplingPoint], DB[waterType])} -> PW | K31: =$A31+0 -> 46168 | L31: 46171 | M31: 0 | N31: 0 | O31: =IFERROR(ROUNDUP(AVERAGE($M31:$N31), 0), "") -> 0 | R31: {=_xlfn.XLOOKUP($B31, DB[samplingPoint], DB[Criteria])} -> 100 | S31: =iferror(ifs($O31>R31, "NOT-PASSED", O31<=R31, "PASSED"), "NA") -> PASSED | T31: FALSE | V31: synced
A32: 46168 | B32: OLD32 | C32: {=_xlfn.XLOOKUP(B32, DB[samplingPoint], DB[samplingTag])} -> DV136.08 | D32: PQ3-Week4 | E32: WT-26-0073 | F32: TRUE | G32: {=_xlfn.XLOOKUP($B32, DB[samplingPoint], DB[noLocation])} -> 12-3-042 | H32: Building 12 | I32: {=_xlfn.XLOOKUP($B32, DB[samplingPoint], DB[location])} -> SAMPLE PREPARATION | J32: {=_xlfn.XLOOKUP($B32, DB[samplingPoint], DB[waterType])} -> PW | K32: =$A32+0 -> 46168 | L32: 46171 | M32: 0 | N32: 0 | O32: =IFERROR(ROUNDUP(AVERAGE($M32:$N32), 0), "") -> 0 | R32: {=_xlfn.XLOOKUP($B32, DB[samplingPoint], DB[Criteria])} -> 100 | S32: =iferror(ifs($O32>R32, "NOT-PASSED", O32<=R32, "PASSED"), "NA") -> PASSED | T32: FALSE | V32: synced
A33: 46168 | B33: OLD33 | C33: {=_xlfn.XLOOKUP(B33, DB[samplingPoint], DB[samplingTag])} -> DV136.09 | D33: PQ3-Week4 | E33: WT-26-0073 | F33: TRUE | G33: {=_xlfn.XLOOKUP($B33, DB[samplingPoint], DB[noLocation])} -> 12-3-042 | H33: Building 12 | I33: {=_xlfn.XLOOKUP($B33, DB[samplingPoint], DB[location])} -> SAMPLE PREPARATION | J33: {=_xlfn.XLOOKUP($B33, DB[samplingPoint], DB[waterType])} -> PW | K33: =$A33+0 -> 46168 | L33: 46171 | M33: 0 | N33: 0 | O33: =IFERROR(ROUNDUP(AVERAGE($M33:$N33), 0), "") -> 0 | R33: {=_xlfn.XLOOKUP($B33, DB[samplingPoint], DB[Criteria])} -> 100 | S33: =iferror(ifs($O33>R33, "NOT-PASSED", O33<=R33, "PASSED"), "NA") -> PASSED | T33: FALSE | V33: synced
... A40: 46168 | B40: OCL17 | C40: {=_xlfn.XLOOKUP(B40, DB[samplingPoint], DB[samplingTag])} -> SV126.15 | D40: PQ3-Week4 | E40: WT-26-0074 | F40: TRUE | G40: {=_xlfn.XLOOKUP($B40, DB[samplingPoint], DB[noLocation])} -> 16-3-075 | H40: Building 16 | I40: {=_xlfn.XLOOKUP($B40, DB[samplingPoint], DB[location])} -> MFG 5 PROCESS (2000L) | J40: {=_xlfn.XLOOKUP($B40, DB[samplingPoint], DB[waterType])} -> PW | K40: =$A40+0 -> 46168 | L40: 46171 | M40: 0 | N40: 0 | O40: =IFERROR(ROUNDUP(AVERAGE($M40:$N40), 0), "") -> 0 | R40: {=_xlfn.XLOOKUP($B40, DB[samplingPoint], DB[Criteria])} -> 100 | S40: =iferror(ifs($O40>R40, "NOT-PASSED", O40<=R40, "PASSED"), "NA") -> PASSED | T40: FALSE | V40: synced
A41: 46168 | B41: OCL21 | C41: {=_xlfn.XLOOKUP(B41, DB[samplingPoint], DB[samplingTag])} -> DV126.05 | D41: PQ3-Week4 | E41: WT-26-0074 | F41: TRUE | G41: {=_xlfn.XLOOKUP($B41, DB[samplingPoint], DB[noLocation])} -> 16-3-054 | H41: Building 16 | I41: {=_xlfn.XLOOKUP($B41, DB[samplingPoint], DB[location])} -> WASHING | J41: {=_xlfn.XLOOKUP($B41, DB[samplingPoint], DB[waterType])} -> PW | K41: =$A41+0 -> 46168 | L41: 46171 | M41: 5 | N41: 33 | O41: =IFERROR(ROUNDUP(AVERAGE($M41:$N41), 0), "") -> 19 | P41: COMMU: PW-M-2-26-005 | R41: {=_xlfn.XLOOKUP($B41, DB[samplingPoint], DB[Criteria])} -> 100 | S41: =iferror(ifs($O41>R41, "NOT-PASSED", O41<=R41, "PASSED"), "NA") -> PASSED | T41: FALSE | V41: synced
A42: 46168 | B42: OCL23 | C42: {=_xlfn.XLOOKUP(B42, DB[samplingPoint], DB[samplingTag])} -> SV126.04 | D42: PQ3-Week4 | E42: WT-26-0074 | F42: TRUE | G42: {=_xlfn.XLOOKUP($B42, DB[samplingPoint], DB[noLocation])} -> 16-2-010 | H42: Building 16 | I42: {=_xlfn.XLOOKUP($B42, DB[samplingPoint], DB[location])} -> WATER SYSTEM (PSG) | J42: {=_xlfn.XLOOKUP($B42, DB[samplingPoint], DB[waterType])} -> PW | K42: =$A42+0 -> 46168 | L42: 46171 | M42: 0 | N42: 0 | O42: =IFERROR(ROUNDUP(AVERAGE($M42:$N42), 0), "") -> 0 | R42: {=_xlfn.XLOOKUP($B42, DB[samplingPoint], DB[Criteria])} -> 100 | S42: =iferror(ifs($O42>R42, "NOT-PASSED", O42<=R42, "PASSED"), "NA") -> PASSED | T42: FALSE | V42: synced
A43: 46171 | B43: OCL13 | C43: {=_xlfn.XLOOKUP(B43, DB[samplingPoint], DB[samplingTag])} -> SV126.19 | D43: PQ3-Week4 | E43: WT-26-0080 | F43: TRUE | G43: {=_xlfn.XLOOKUP($B43, DB[samplingPoint], DB[noLocation])} -> 16-3-087 | H43: Building 16 | I43: {=_xlfn.XLOOKUP($B43, DB[samplingPoint], DB[location])} -> CIP 2 (EQUIPMENT REQUIREMENT) | J43: {=_xlfn.XLOOKUP($B43, DB[samplingPoint], DB[waterType])} -> PW | K43: =$A43+1 -> 46172 | L43: 46175 | M43: 0 | N43: 0 | O43: =IFERROR(ROUNDUP(AVERAGE($M43:$N43), 0), "") -> 0 | R43: {=_xlfn.XLOOKUP($B43, DB[samplingPoint], DB[Criteria])} -> 100 | S43: =iferror(ifs($O43>R43, "NOT-PASSED", O43<=R43, "PASSED"), "NA") -> PASSED | T43: FALSE | V43: synced
A44: 46171 | B44: GOSD08 | C44: {=_xlfn.XLOOKUP(B44, DB[samplingPoint], DB[samplingTag])} -> SV117.01 | D44: PQ3-Week4 | E44: WT-26-0075 | F44: TRUE | G44: {=_xlfn.XLOOKUP($B44, DB[samplingPoint], DB[noLocation])} -> WATER SYSTEM (B10) | H44: Building 10 | I44: {=_xlfn.XLOOKUP($B44, DB[samplingPoint], DB[location])} -> Return loop (B10) | J44: {=_xlfn.XLOOKUP($B44, DB[samplingPoint], DB[waterType])} -> PW | K44: =$A44+1 -> 46172 | L44: 46175 | M44: 0 | N44: 0 | O44: =IFERROR(ROUNDUP(AVERAGE($M44:$N44), 0), "") -> 0 | R44: {=_xlfn.XLOOKUP($B44, DB[samplingPoint], DB[Criteria])} -> 100 | S44: =iferror(ifs($O44>R44, "NOT-PASSED", O44<=R44, "PASSED"), "NA") -> PASSED | T44: FALSE | V44: synced
A45: 46171 | B45: OSD01 | C45: {=_xlfn.XLOOKUP(B45, DB[samplingPoint], DB[samplingTag])} -> SV116.15 | D45: PQ3-Week4 | E45: WT-26-0075 | F45: TRUE | G45: {=_xlfn.XLOOKUP($B45, DB[samplingPoint], DB[noLocation])} -> 10-4-012 | H45: Building 10 | I45: {=_xlfn.XLOOKUP($B45, DB[samplingPoint], DB[location])} -> CIP SKID-1 FOR BIN WASHING-1 | J45: {=_xlfn.XLOOKUP($B45, DB[samplingPoint], DB[waterType])} -> PW | K45: =$A45+1 -> 46172 | L45: 46175 | M45: 0 | N45: 0 | O45: =IFERROR(ROUNDUP(AVERAGE($M45:$N45), 0), "") -> 0 | R45: {=_xlfn.XLOOKUP($B45, DB[samplingPoint], DB[Criteria])} -> 100 | S45: =iferror(ifs($O45>R45, "NOT-PASSED", O45<=R45, "PASSED"), "NA") -> PASSED | T45: FALSE | V45: synced
A46: 46171 | B46: OSD02 | C46: {=_xlfn.XLOOKUP(B46, DB[samplingPoint], DB[samplingTag])} -> SV116.16 | D46: PQ3-Week4 | E46: WT-26-0075 | F46: TRUE | G46: {=_xlfn.XLOOKUP($B46, DB[samplingPoint], DB[noLocation])} -> 10-4-012 | H46: Building 10 | I46: {=_xlfn.XLOOKUP($B46, DB[samplingPoint], DB[location])} -> WIP SKID-3 FOR GRANULATION POTENT | J46: {=_xlfn.XLOOKUP($B46, DB[samplingPoint], DB[waterType])} -> PW | K46: =$A46+1 -> 46172 | L46: 46175 | M46: 0 | N46: 0 | O46: =IFERROR(ROUNDUP(AVERAGE($M46:$N46), 0), "") -> 0 | R46: {=_xlfn.XLOOKUP($B46, DB[samplingPoint], DB[Criteria])} -> 100 | S46: =iferror(ifs($O46>R46, "NOT-PASSED", O46<=R46, "PASSED"), "NA") -> PASSED | T46: FALSE | V46: synced
...

Sheet wfi-pus
A1: samplingDate | B1: samplingPoint | C1: samplingTag | D1: recordStatus | E1: worksheet No. | F1: worksheetCreate | G1: noLocation | H1: building | I1: location | J1: waterType | K1: performedDate | L1: determinedDate | M1: result1 | N1: resultAvg | O1: qualityEvent | P1: comment | Q1: criteria | R1: statusResult | S1: Exclude | T1: status | U1: syncStatus
A2: 46170 | B2: WFI06 | C2: {=_xlfn.XLOOKUP(B2, DB[samplingPoint], DB[samplingTag])} -> SV216.05 | D2: PQ3-Day4 | E2: WP-26-0080 | F2: TRUE | G2: {=_xlfn.XLOOKUP($B2, DB[samplingPoint], DB[noLocation])} -> 16-1-110 | H2: Building 16 | I2: {=_xlfn.XLOOKUP($B2, DB[samplingPoint], DB[location])} -> DISINFECTANT PREPARATION | J2: {=_xlfn.XLOOKUP($B2, DB[samplingPoint], DB[waterType])} -> WFI | K2: =$A2+2 -> 46172 | L2: 46175 | M2: 0 | N2: =iferror(ROUNDUP(AVERAGE($M2), 0),"") -> 0 | R2: =iferror(ifs($N2>Q2, "NOT-PASSED", N2<=Q2, "PASSED"), "NA") -> PASSED | S2: FALSE | U2: synced
A3: 46170 | B3: WFI09 | C3: {=_xlfn.XLOOKUP(B3, DB[samplingPoint], DB[samplingTag])} -> SV216.10 | D3: PQ3-Day4 | E3: WP-26-0080 | F3: TRUE | G3: {=_xlfn.XLOOKUP($B3, DB[samplingPoint], DB[noLocation])} -> 16-1-105 | H3: Building 16 | I3: {=_xlfn.XLOOKUP($B3, DB[samplingPoint], DB[location])} -> WASHING/TUNNEL-01 | J3: {=_xlfn.XLOOKUP($B3, DB[samplingPoint], DB[waterType])} -> WFI | K3: =$A3+2 -> 46172 | L3: 46175 | M3: 0 | N3: =iferror(ROUNDUP(AVERAGE($M3), 0),"") -> 0 | R3: =iferror(ifs($N3>Q3, "NOT-PASSED", N3<=Q3, "PASSED"), "NA") -> PASSED | S3: FALSE | U3: synced
A4: 46171 | B4: WFI10 | C4: {=_xlfn.XLOOKUP(B4, DB[samplingPoint], DB[samplingTag])} -> POU HE216.04 | D4: PQ3-Day5 | E4: WP-26-0081 | F4: TRUE | G4: {=_xlfn.XLOOKUP($B4, DB[samplingPoint], DB[noLocation])} -> 16-1-114 | H4: Building 16 | I4: {=_xlfn.XLOOKUP($B4, DB[samplingPoint], DB[location])} -> COMPOUNDING-02 | J4: {=_xlfn.XLOOKUP($B4, DB[samplingPoint], DB[waterType])} -> WFI | K4: =$A4+1 -> 46172 | L4: 46175 | M4: 0 | N4: =iferror(ROUNDUP(AVERAGE($M4), 0),"") -> 0 | R4: =iferror(ifs($N4>Q4, "NOT-PASSED", N4<=Q4, "PASSED"), "NA") -> PASSED | S4: FALSE | U4: synced
A5: 46171 | B5: WFI11 | C5: {=_xlfn.XLOOKUP(B5, DB[samplingPoint], DB[samplingTag])} -> POU HE216.05 | D5: PQ3-Day5 | E5: WP-26-0081 | F5: TRUE | G5: {=_xlfn.XLOOKUP($B5, DB[samplingPoint], DB[noLocation])} -> 16-1-114 | H5: Building 16 | I5: {=_xlfn.XLOOKUP($B5, DB[samplingPoint], DB[location])} -> COMPOUNDING-02 | J5: {=_xlfn.XLOOKUP($B5, DB[samplingPoint], DB[waterType])} -> WFI | K5: =$A5+1 -> 46172 | L5: 46175 | M5: 0 | N5: =iferror(ROUNDUP(AVERAGE($M5), 0),"") -> 0 | R5: =iferror(ifs($N5>Q5, "NOT-PASSED", N5<=Q5, "PASSED"), "NA") -> PASSED | S5: FALSE | U5: synced
A6: 46175 | B6: GWFI01 | C6: {=_xlfn.XLOOKUP(B6, DB[samplingPoint], DB[samplingTag])} -> V12-4 | D6: PQ3-Day1 | E6: WP-26-0082 | F6: TRUE | G6: {=_xlfn.XLOOKUP($B6, DB[samplingPoint], DB[noLocation])} -> 16-2-010 | H6: Building 16 | I6: {=_xlfn.XLOOKUP($B6, DB[samplingPoint], DB[location])} -> AFTER WFI GENERATOR | J6: {=_xlfn.XLOOKUP($B6, DB[samplingPoint], DB[waterType])} -> WFI | K6: =$A6+1 -> 46176 | L6: 46179 | M6: 0 | N6: =iferror(ROUNDUP(AVERAGE($M6), 0),"") -> 0 | R6: =iferror(ifs($N6>Q6, "NOT-PASSED", N6<=Q6, "PASSED"), "NA") -> PASSED | S6: FALSE | U6: synced
A7: 46175 | B7: GWFI02 | C7: {=_xlfn.XLOOKUP(B7, DB[samplingPoint], DB[samplingTag])} -> SV213.01 | D7: PQ3-Day1 | E7: WP-26-0082 | F7: TRUE | G7: {=_xlfn.XLOOKUP($B7, DB[samplingPoint], DB[noLocation])} -> 16-2-010 | H7: Building 16 | I7: {=_xlfn.XLOOKUP($B7, DB[samplingPoint], DB[location])} -> AFTER STORAGE TANK | J7: {=_xlfn.XLOOKUP($B7, DB[samplingPoint], DB[waterType])} -> WFI | K7: =$A7+1 -> 46176 | L7: 46179 | M7: 0 | N7: =iferror(ROUNDUP(AVERAGE($M7), 0),"") -> 0 | R7: =iferror(ifs($N7>Q7, "NOT-PASSED", N7<=Q7, "PASSED"), "NA") -> PASSED | S7: FALSE | U7: synced
A8: 46175 | B8: GWFI03 | C8: {=_xlfn.XLOOKUP(B8, DB[samplingPoint], DB[samplingTag])} -> SV217.01 | D8: PQ3-Day1 | E8: WP-26-0082 | F8: TRUE | G8: {=_xlfn.XLOOKUP($B8, DB[samplingPoint], DB[noLocation])} -> 16-2-010 | H8: Building 16 | I8: {=_xlfn.XLOOKUP($B8, DB[samplingPoint], DB[location])} -> RETURN LOOP | J8: {=_xlfn.XLOOKUP($B8, DB[samplingPoint], DB[waterType])} -> WFI | K8: =$A8+1 -> 46176 | L8: 46179 | M8: 0 | N8: =iferror(ROUNDUP(AVERAGE($M8), 0),"") -> 0 | R8: =iferror(ifs($N8>Q8, "NOT-PASSED", N8<=Q8, "PASSED"), "NA") -> PASSED | S8: FALSE | U8: synced
A9: 46175 | B9: WFI03 | C9: {=_xlfn.XLOOKUP(B9, DB[samplingPoint], DB[samplingTag])} -> SV216.03 | D9: PQ3-Day1 | E9: WP-26-0082 | F9: TRUE | G9: {=_xlfn.XLOOKUP($B9, DB[samplingPoint], DB[noLocation])} -> 16-1-096 | H9: Building 16 | I9: {=_xlfn.XLOOKUP($B9, DB[samplingPoint], DB[location])} -> WASHING/TUNNEL-02 | J9: {=_xlfn.XLOOKUP($B9, DB[samplingPoint], DB[waterType])} -> WFI | K9: =$A9+1 -> 46176 | L9: 46179 | M9: 0 | N9: =iferror(ROUNDUP(AVERAGE($M9), 0),"") -> 0 | R9: =iferror(ifs($N9>Q9, "NOT-PASSED", N9<=Q9, "PASSED"), "NA") -> PASSED | S9: FALSE | U9: synced
A10: 46175 | B10: WFI04 | C10: {=_xlfn.XLOOKUP(B10, DB[samplingPoint], DB[samplingTag])} -> POU HE216.03 | D10: PQ3-Day1 | E10: WP-26-0082 | F10: TRUE | G10: {=_xlfn.XLOOKUP($B10, DB[samplingPoint], DB[noLocation])} -> 16-1-082 | H10: Building 16 | I10: {=_xlfn.XLOOKUP($B10, DB[samplingPoint], DB[location])} -> WASHING | J10: {=_xlfn.XLOOKUP($B10, DB[samplingPoint], DB[waterType])} -> WFI | K10: =$A10+1 -> 46176 | L10: 46179 | M10: 0 | N10: =iferror(ROUNDUP(AVERAGE($M10), 0),"") -> 0 | R10: =iferror(ifs($N10>Q10, "NOT-PASSED", N10<=Q10, "PASSED"), "NA") -> PASSED | S10: FALSE | U10: synced
A11: 46175 | B11: WFI05 | C11: {=_xlfn.XLOOKUP(B11, DB[samplingPoint], DB[samplingTag])} -> SV216.06 | D11: PQ3-Day1 | E11: WP-26-0082 | F11: TRUE | G11: {=_xlfn.XLOOKUP($B11, DB[samplingPoint], DB[noLocation])} -> 16-1-082 | H11: Building 16 | I11: {=_xlfn.XLOOKUP($B11, DB[samplingPoint], DB[location])} -> WASHING | J11: {=_xlfn.XLOOKUP($B11, DB[samplingPoint], DB[waterType])} -> WFI | K11: =$A11+1 -> 46176 | L11: 46179 | M11: 0 | N11: =iferror(ROUNDUP(AVERAGE($M11), 0),"") -> 0 | R11: =iferror(ifs($N11>Q11, "NOT-PASSED", N11<=Q11, "PASSED"), "NA") -> PASSED | S11: FALSE | U11: synced
A12: 46177 | B12: WFI01 | C12: {=_xlfn.XLOOKUP(B12, DB[samplingPoint], DB[samplingTag])} -> POU HE216.01 | D12: PQ3-Day2 | E12: WP-26-0083 | F12: TRUE | G12: {=_xlfn.XLOOKUP($B12, DB[samplingPoint], DB[noLocation])} -> 16-1-107 | H12: Building 16 | I12: {=_xlfn.XLOOKUP($B12, DB[samplingPoint], DB[location])} -> COMPOUNDING-01 | J12: {=_xlfn.XLOOKUP($B12, DB[samplingPoint], DB[waterType])} -> WFI | K12: =$A12+1 -> 46178 | L12: 46181 | M12: 0 | N12: =iferror(ROUNDUP(AVERAGE($M12), 0),"") -> 0 | R12: =iferror(ifs($N12>Q12, "NOT-PASSED", N12<=Q12, "PASSED"), "NA") -> PASSED | S12: FALSE | U12: synced
A13: 46177 | B13: WFI02 | C13: {=_xlfn.XLOOKUP(B13, DB[samplingPoint], DB[samplingTag])} -> POU HE216.02 | D13: PQ3-Day2 | E13: WP-26-0083 | F13: TRUE | G13: {=_xlfn.XLOOKUP($B13, DB[samplingPoint], DB[noLocation])} -> 16-1-107 | H13: Building 16 | I13: {=_xlfn.XLOOKUP($B13, DB[samplingPoint], DB[location])} -> COMPOUNDING-01 | J13: {=_xlfn.XLOOKUP($B13, DB[samplingPoint], DB[waterType])} -> WFI | K13: =$A13+1 -> 46178 | L13: 46181 | M13: 0 | N13: =iferror(ROUNDUP(AVERAGE($M13), 0),"") -> 0 | R13: =iferror(ifs($N13>Q13, "NOT-PASSED", N13<=Q13, "PASSED"), "NA") -> PASSED | S13: FALSE | U13: synced
A14: 46177 | B14: WFI09 | C14: {=_xlfn.XLOOKUP(B14, DB[samplingPoint], DB[samplingTag])} -> SV216.10 | D14: PQ3-Day2 | E14: WP-26-0083 | F14: TRUE | G14: {=_xlfn.XLOOKUP($B14, DB[samplingPoint], DB[noLocation])} -> 16-1-105 | H14: Building 16 | I14: {=_xlfn.XLOOKUP($B14, DB[samplingPoint], DB[location])} -> WASHING/TUNNEL-01 | J14: {=_xlfn.XLOOKUP($B14, DB[samplingPoint], DB[waterType])} -> WFI | K14: =$A14+1 -> 46178 | L14: 46181 | M14: 0 | N14: =iferror(ROUNDUP(AVERAGE($M14), 0),"") -> 0 | R14: =iferror(ifs($N14>Q14, "NOT-PASSED", N14<=Q14, "PASSED"), "NA") -> PASSED | S14: FALSE | U14: synced
A15: 46178 | B15: WFI06 | C15: {=_xlfn.XLOOKUP(B15, DB[samplingPoint], DB[samplingTag])} -> SV216.05 | D15: PQ3-Day3 | E15: WP-26-0084 | F15: TRUE | G15: {=_xlfn.XLOOKUP($B15, DB[samplingPoint], DB[noLocation])} -> 16-1-110 | H15: Building 16 | I15: {=_xlfn.XLOOKUP($B15, DB[samplingPoint], DB[location])} -> DISINFECTANT PREPARATION | J15: {=_xlfn.XLOOKUP($B15, DB[samplingPoint], DB[waterType])} -> WFI | K15: =$A15+0 -> 46178 | L15: 46181 | M15: 0 | N15: =iferror(ROUNDUP(AVERAGE($M15), 0),"") -> 0 | R15: =iferror(ifs($N15>Q15, "NOT-PASSED", N15<=Q15, "PASSED"), "NA") -> PASSED | S15: FALSE | U15: synced
A16: 46178 | B16: WFI07 | C16: {=_xlfn.XLOOKUP(B16, DB[samplingPoint], DB[samplingTag])} -> SV216.02 | D16: PQ3-Day3 | E16: WP-26-0084 | F16: TRUE | G16: {=_xlfn.XLOOKUP($B16, DB[samplingPoint], DB[noLocation])} -> 16-1-098 | H16: Building 16 | I16: {=_xlfn.XLOOKUP($B16, DB[samplingPoint], DB[location])} -> CIP/SIP | J16: {=_xlfn.XLOOKUP($B16, DB[samplingPoint], DB[waterType])} -> WFI | K16: =$A16+0 -> 46178 | L16: 46181 | M16: 0 | N16: 0 | R16: =iferror(ifs($N16>Q16, "NOT-PASSED", N16<=Q16, "PASSED"), "NA") -> PASSED | S16: FALSE | U16: synced
A17: 46178 | B17: WFI08 | C17: {=_xlfn.XLOOKUP(B17, DB[samplingPoint], DB[samplingTag])} -> SV216.04 | D17: PQ3-Day3 | E17: WP-26-0084 | F17: TRUE | G17: {=_xlfn.XLOOKUP($B17, DB[samplingPoint], DB[noLocation])} -> 16-1-098 | H17: Building 16 | I17: {=_xlfn.XLOOKUP($B17, DB[samplingPoint], DB[location])} -> CIP/SIP | J17: {=_xlfn.XLOOKUP($B17, DB[samplingPoint], DB[waterType])} -> WFI | K17: =$A17+0 -> 46178 | L17: 46181 | M17: 0 | N17: =iferror(ROUNDUP(AVERAGE($M17), 0),"") -> 0 | R17: =iferror(ifs($N17>Q17, "NOT-PASSED", N17<=Q17, "PASSED"), "NA") -> PASSED | S17: FALSE | U17: synced
A18: 46178 | B18: WFI10 | C18: {=_xlfn.XLOOKUP(B18, DB[samplingPoint], DB[samplingTag])} -> POU HE216.04 | D18: PQ3-Day3 | E18: WP-26-0084 | F18: TRUE | G18: {=_xlfn.XLOOKUP($B18, DB[samplingPoint], DB[noLocation])} -> 16-1-114 | H18: Building 16 | I18: {=_xlfn.XLOOKUP($B18, DB[samplingPoint], DB[location])} -> COMPOUNDING-02 | J18: {=_xlfn.XLOOKUP($B18, DB[samplingPoint], DB[waterType])} -> WFI | K18: =$A18+0 -> 46178 | L18: 46181 | M18: 0 | N18: =iferror(ROUNDUP(AVERAGE($M18), 0),"") -> 0 | R18: =iferror(ifs($N18>Q18, "NOT-PASSED", N18<=Q18, "PASSED"), "NA") -> PASSED | S18: FALSE | U18: synced
A19: 46178 | B19: WFI11 | C19: {=_xlfn.XLOOKUP(B19, DB[samplingPoint], DB[samplingTag])} -> POU HE216.05 | D19: PQ3-Day3 | E19: WP-26-0084 | F19: TRUE | G19: {=_xlfn.XLOOKUP($B19, DB[samplingPoint], DB[noLocation])} -> 16-1-114 | H19: Building 16 | I19: {=_xlfn.XLOOKUP($B19, DB[samplingPoint], DB[location])} -> COMPOUNDING-02 | J19: {=_xlfn.XLOOKUP($B19, DB[samplingPoint], DB[waterType])} -> WFI | K19: =$A19+0 -> 46178 | L19: 46181 | M19: 0 | N19: =iferror(ROUNDUP(AVERAGE($M19), 0),"") -> 0 | R19: =iferror(ifs($N19>Q19, "NOT-PASSED", N19<=Q19, "PASSED"), "NA") -> PASSED | S19: FALSE | U19: synced
A20: 46181 | B20: GWFI01 | C20: {=_xlfn.XLOOKUP(B20, DB[samplingPoint], DB[samplingTag])} -> V12-4 | D20: PQ3-Day1 | E20: WP-26-0085 | F20: TRUE | G20: {=_xlfn.XLOOKUP($B20, DB[samplingPoint], DB[noLocation])} -> 16-2-010 | H20: Building 16 | I20: {=_xlfn.XLOOKUP($B20, DB[samplingPoint], DB[location])} -> AFTER WFI GENERATOR | J20: {=_xlfn.XLOOKUP($B20, DB[samplingPoint], DB[waterType])} -> WFI | K20: =$A20+1 -> 46182 | L20: 46185 | M20: 0 | N20: =iferror(ROUNDUP(AVERAGE($M20), 0),"") -> 0 | R20: =iferror(ifs($N20>Q20, "NOT-PASSED", N20<=Q20, "PASSED"), "NA") -> PASSED | S20: FALSE | U20: synced
A21: 46181 | B21: GWFI02 | C21: {=_xlfn.XLOOKUP(B21, DB[samplingPoint], DB[samplingTag])} -> SV213.01 | D21: PQ3-Day1 | E21: WP-26-0085 | F21: TRUE | G21: {=_xlfn.XLOOKUP($B21, DB[samplingPoint], DB[noLocation])} -> 16-2-010 | H21: Building 16 | I21: {=_xlfn.XLOOKUP($B21, DB[samplingPoint], DB[location])} -> AFTER STORAGE TANK | J21: {=_xlfn.XLOOKUP($B21, DB[samplingPoint], DB[waterType])} -> WFI | K21: =$A21+1 -> 46182 | L21: 46185 | M21: 0 | N21: =iferror(ROUNDUP(AVERAGE($M21), 0),"") -> 0 | R21: =iferror(ifs($N21>Q21, "NOT-PASSED", N21<=Q21, "PASSED"), "NA") -> PASSED | S21: FALSE | U21: synced
A22: 46181 | B22: GWFI03 | C22: {=_xlfn.XLOOKUP(B22, DB[samplingPoint], DB[samplingTag])} -> SV217.01 | D22: PQ3-Day1 | E22: WP-26-0085 | F22: TRUE | G22: {=_xlfn.XLOOKUP($B22, DB[samplingPoint], DB[noLocation])} -> 16-2-010 | H22: Building 16 | I22: {=_xlfn.XLOOKUP($B22, DB[samplingPoint], DB[location])} -> RETURN LOOP | J22: {=_xlfn.XLOOKUP($B22, DB[samplingPoint], DB[waterType])} -> WFI | K22: =$A22+1 -> 46182 | L22: 46185 | M22: 0 | N22: =iferror(ROUNDUP(AVERAGE($M22), 0),"") -> 0 | R22: =iferror(ifs($N22>Q22, "NOT-PASSED", N22<=Q22, "PASSED"), "NA") -> PASSED | S22: FALSE | U22: synced
A23: 46181 | B23: WFI07 | C23: {=_xlfn.XLOOKUP(B23, DB[samplingPoint], DB[samplingTag])} -> SV216.02 | D23: PQ3-Day1 | E23: WP-26-0085 | F23: TRUE | G23: {=_xlfn.XLOOKUP($B23, DB[samplingPoint], DB[noLocation])} -> 16-1-098 | H23: Building 16 | I23: {=_xlfn.XLOOKUP($B23, DB[samplingPoint], DB[location])} -> CIP/SIP | J23: {=_xlfn.XLOOKUP($B23, DB[samplingPoint], DB[waterType])} -> WFI | K23: =$A23+1 -> 46182 | L23: 46185 | M23: 0 | N23: =iferror(ROUNDUP(AVERAGE($M23), 0),"") -> 0 | R23: =iferror(ifs($N23>Q23, "NOT-PASSED", N23<=Q23, "PASSED"), "NA") -> PASSED | S23: FALSE | U23: synced
A24: 46181 | B24: WFI08 | C24: {=_xlfn.XLOOKUP(B24, DB[samplingPoint], DB[samplingTag])} -> SV216.04 | D24: PQ3-Day1 | E24: WP-26-0085 | F24: TRUE | G24: {=_xlfn.XLOOKUP($B24, DB[samplingPoint], DB[noLocation])} -> 16-1-098 | H24: Building 16 | I24: {=_xlfn.XLOOKUP($B24, DB[samplingPoint], DB[location])} -> CIP/SIP | J24: {=_xlfn.XLOOKUP($B24, DB[samplingPoint], DB[waterType])} -> WFI | K24: =$A24+1 -> 46182 | L24: 46185 | M24: 0 | N24: =iferror(ROUNDUP(AVERAGE($M24), 0),"") -> 0 | R24: =iferror(ifs($N24>Q24, "NOT-PASSED", N24<=Q24, "PASSED"), "NA") -> PASSED | S24: FALSE | U24: synced
A25: 46182 | B25: WFI03 | C25: {=_xlfn.XLOOKUP(B25, DB[samplingPoint], DB[samplingTag])} -> SV216.03 | D25: PQ3-Day2 | E25: WP-26-0086 | F25: TRUE | G25: {=_xlfn.XLOOKUP($B25, DB[samplingPoint], DB[noLocation])} -> 16-1-096 | H25: Building 16 | I25: {=_xlfn.XLOOKUP($B25, DB[samplingPoint], DB[location])} -> WASHING/TUNNEL-02 | J25: {=_xlfn.XLOOKUP($B25, DB[samplingPoint], DB[waterType])} -> WFI | K25: =$A25+0 -> 46182 | L25: 46185 | M25: 0 | N25: =iferror(ROUNDUP(AVERAGE($M25), 0),"") -> 0 | R25: =iferror(ifs($N25>Q25, "NOT-PASSED", N25<=Q25, "PASSED"), "NA") -> PASSED | S25: FALSE | U25: synced
A26: 46182 | B26: WFI04 | C26: {=_xlfn.XLOOKUP(B26, DB[samplingPoint], DB[samplingTag])} -> POU HE216.03 | D26: PQ3-Day2 | E26: WP-26-0086 | F26: TRUE | G26: {=_xlfn.XLOOKUP($B26, DB[samplingPoint], DB[noLocation])} -> 16-1-082 | H26: Building 16 | I26: {=_xlfn.XLOOKUP($B26, DB[samplingPoint], DB[location])} -> WASHING | J26: {=_xlfn.XLOOKUP($B26, DB[samplingPoint], DB[waterType])} -> WFI | K26: =$A26+0 -> 46182 | L26: 46185 | M26: 0 | N26: =iferror(ROUNDUP(AVERAGE($M26), 0),"") -> 0 | R26: =iferror(ifs($N26>Q26, "NOT-PASSED", N26<=Q26, "PASSED"), "NA") -> PASSED | S26: FALSE | U26: synced
A27: 46182 | B27: WFI05 | C27: {=_xlfn.XLOOKUP(B27, DB[samplingPoint], DB[samplingTag])} -> SV216.06 | D27: PQ3-Day2 | E27: WP-26-0086 | F27: TRUE | G27: {=_xlfn.XLOOKUP($B27, DB[samplingPoint], DB[noLocation])} -> 16-1-082 | H27: Building 16 | I27: {=_xlfn.XLOOKUP($B27, DB[samplingPoint], DB[location])} -> WASHING | J27: {=_xlfn.XLOOKUP($B27, DB[samplingPoint], DB[waterType])} -> WFI | K27: =$A27+0 -> 46182 | L27: 46185 | M27: 0 | N27: =iferror(ROUNDUP(AVERAGE($M27), 0),"") -> 0 | R27: =iferror(ifs($N27>Q27, "NOT-PASSED", N27<=Q27, "PASSED"), "NA") -> PASSED | S27: FALSE | U27: synced
A28: 46183 | B28: WFI01 | C28: {=_xlfn.XLOOKUP(B28, DB[samplingPoint], DB[samplingTag])} -> POU HE216.01 | D28: PQ3-Day3 | E28: WP-26-0087 | F28: TRUE | G28: {=_xlfn.XLOOKUP($B28, DB[samplingPoint], DB[noLocation])} -> 16-1-107 | H28: Building 16 | I28: {=_xlfn.XLOOKUP($B28, DB[samplingPoint], DB[location])} -> COMPOUNDING-01 | J28: {=_xlfn.XLOOKUP($B28, DB[samplingPoint], DB[waterType])} -> WFI | K28: =$A28+1 -> 46184 | L28: 46188 | M28: 16 | N28: =iferror(ROUNDUP(AVERAGE($M28), 0),"") -> 16 | O28: IR: 1100003786 | R28: =iferror(ifs($N28>Q28, "NOT-PASSED", N28<=Q28, "PASSED"), "NA") -> NOT-PASSED | S28: FALSE | U28: synced
A29: 46183 | B29: WFI02 | C29: {=_xlfn.XLOOKUP(B29, DB[samplingPoint], DB[samplingTag])} -> POU HE216.02 | D29: PQ3-Day3 | E29: WP-26-0087 | F29: TRUE | G29: {=_xlfn.XLOOKUP($B29, DB[samplingPoint], DB[noLocation])} -> 16-1-107 | H29: Building 16 | I29: {=_xlfn.XLOOKUP($B29, DB[samplingPoint], DB[location])} -> COMPOUNDING-01 | J29: {=_xlfn.XLOOKUP($B29, DB[samplingPoint], DB[waterType])} -> WFI | K29: =$A29+1 -> 46184 | L29: 46188 | M29: 0 | N29: =iferror(ROUNDUP(AVERAGE($M29), 0),"") -> 0 | R29: =iferror(ifs($N29>Q29, "NOT-PASSED", N29<=Q29, "PASSED"), "NA") -> PASSED | S29: FALSE | U29: synced
A30: 46184 | B30: WFI06 | C30: {=_xlfn.XLOOKUP(B30, DB[samplingPoint], DB[samplingTag])} -> SV216.05 | D30: PQ3-Day4 | E30: WP-26-0088 | F30: TRUE | G30: {=_xlfn.XLOOKUP($B30, DB[samplingPoint], DB[noLocation])} -> 16-1-110 | H30: Building 16 | I30: {=_xlfn.XLOOKUP($B30, DB[samplingPoint], DB[location])} -> DISINFECTANT PREPARATION | J30: {=_xlfn.XLOOKUP($B30, DB[samplingPoint], DB[waterType])} -> WFI | K30: =$A30+0 -> 46184 | L30: 46188 | M30: 0 | N30: =iferror(ROUNDUP(AVERAGE($M30), 0),"") -> 0 | R30: =iferror(ifs($N30>Q30, "NOT-PASSED", N30<=Q30, "PASSED"), "NA") -> PASSED | S30: FALSE | U30: synced
A31: 46184 | B31: WFI09 | C31: {=_xlfn.XLOOKUP(B31, DB[samplingPoint], DB[samplingTag])} -> SV216.10 | D31: PQ3-Day4 | E31: WP-26-0088 | F31: TRUE | G31: {=_xlfn.XLOOKUP($B31, DB[samplingPoint], DB[noLocation])} -> 16-1-105 | H31: Building 16 | I31: {=_xlfn.XLOOKUP($B31, DB[samplingPoint], DB[location])} -> WASHING/TUNNEL-01 | J31: {=_xlfn.XLOOKUP($B31, DB[samplingPoint], DB[waterType])} -> WFI | K31: =$A31+0 -> 46184 | L31: 46188 | M31: 0 | N31: =iferror(ROUNDUP(AVERAGE($M31), 0),"") -> 0 | R31: =iferror(ifs($N31>Q31, "NOT-PASSED", N31<=Q31, "PASSED"), "NA") -> PASSED | S31: FALSE | U31: synced
A32: 46185 | B32: WFI10 | C32: {=_xlfn.XLOOKUP(B32, DB[samplingPoint], DB[samplingTag])} -> POU HE216.04 | D32: PQ3-Day5 | E32: WP-26-0089 | F32: TRUE | G32: {=_xlfn.XLOOKUP($B32, DB[samplingPoint], DB[noLocation])} -> 16-1-114 | H32: Building 16 | I32: {=_xlfn.XLOOKUP($B32, DB[samplingPoint], DB[location])} -> COMPOUNDING-02 | J32: {=_xlfn.XLOOKUP($B32, DB[samplingPoint], DB[waterType])} -> WFI | K32: =$A32+0 -> 46185 | L32: 46188 | M32: 0 | N32: =iferror(ROUNDUP(AVERAGE($M32), 0),"") -> 0 | R32: =iferror(ifs($N32>Q32, "NOT-PASSED", N32<=Q32, "PASSED"), "NA") -> PASSED | S32: FALSE | U32: synced
A33: 46185 | B33: WFI11 | C33: {=_xlfn.XLOOKUP(B33, DB[samplingPoint], DB[samplingTag])} -> POU HE216.05 | D33: PQ3-Day5 | E33: WP-26-0089 | F33: TRUE | G33: {=_xlfn.XLOOKUP($B33, DB[samplingPoint], DB[noLocation])} -> 16-1-114 | H33: Building 16 | I33: {=_xlfn.XLOOKUP($B33, DB[samplingPoint], DB[location])} -> COMPOUNDING-02 | J33: {=_xlfn.XLOOKUP($B33, DB[samplingPoint], DB[waterType])} -> WFI | K33: =$A33+0 -> 46185 | L33: 46188 | M33: 0 | N33: =iferror(ROUNDUP(AVERAGE($M33), 0),"") -> 0 | R33: =iferror(ifs($N33>Q33, "NOT-PASSED", N33<=Q33, "PASSED"), "NA") -> PASSED | S33: FALSE | U33: synced
A34: 46188 | B34: GWFI01 | C34: {=_xlfn.XLOOKUP(B34, DB[samplingPoint], DB[samplingTag])} -> V12-4 | D34: PQ3-Day1 | E34: WP-26-0090 | F34: TRUE | G34: {=_xlfn.XLOOKUP($B34, DB[samplingPoint], DB[noLocation])} -> 16-2-010 | H34: Building 16 | I34: {=_xlfn.XLOOKUP($B34, DB[samplingPoint], DB[location])} -> AFTER WFI GENERATOR | J34: {=_xlfn.XLOOKUP($B34, DB[samplingPoint], DB[waterType])} -> WFI | K34: =$A34+1 -> 46189 | L34: 46192 | M34: 0 | N34: =iferror(ROUNDUP(AVERAGE($M34), 0),"") -> 0 | R34: =iferror(ifs($N34>Q34, "NOT-PASSED", N34<=Q34, "PASSED"), "NA") -> PASSED | S34: FALSE | U34: synced
A35: 46188 | B35: GWFI02 | C35: {=_xlfn.XLOOKUP(B35, DB[samplingPoint], DB[samplingTag])} -> SV213.01 | D35: PQ3-Day1 | E35: WP-26-0090 | F35: TRUE | G35: {=_xlfn.XLOOKUP($B35, DB[samplingPoint], DB[noLocation])} -> 16-2-010 | H35: Building 16 | I35: {=_xlfn.XLOOKUP($B35, DB[samplingPoint], DB[location])} -> AFTER STORAGE TANK | J35: {=_xlfn.XLOOKUP($B35, DB[samplingPoint], DB[waterType])} -> WFI | K35: =$A35+1 -> 46189 | L35: 46192 | M35: 0 | N35: =iferror(ROUNDUP(AVERAGE($M35), 0),"") -> 0 | R35: =iferror(ifs($N35>Q35, "NOT-PASSED", N35<=Q35, "PASSED"), "NA") -> PASSED | S35: FALSE | U35: synced
A36: 46188 | B36: GWFI03 | C36: {=_xlfn.XLOOKUP(B36, DB[samplingPoint], DB[samplingTag])} -> SV217.01 | D36: PQ3-Day1 | E36: WP-26-0090 | F36: TRUE | G36: {=_xlfn.XLOOKUP($B36, DB[samplingPoint], DB[noLocation])} -> 16-2-010 | H36: Building 16 | I36: {=_xlfn.XLOOKUP($B36, DB[samplingPoint], DB[location])} -> RETURN LOOP | J36: {=_xlfn.XLOOKUP($B36, DB[samplingPoint], DB[waterType])} -> WFI | K36: =$A36+1 -> 46189 | L36: 46192 | M36: 0 | N36: =iferror(ROUNDUP(AVERAGE($M36), 0),"") -> 0 | R36: =iferror(ifs($N36>Q36, "NOT-PASSED", N36<=Q36, "PASSED"), "NA") -> PASSED | S36: FALSE | U36: synced
A37: 46188 | B37: WFI07 | C37: {=_xlfn.XLOOKUP(B37, DB[samplingPoint], DB[samplingTag])} -> SV216.02 | D37: PQ3-Day1 | E37: WP-26-0090 | F37: TRUE | G37: {=_xlfn.XLOOKUP($B37, DB[samplingPoint], DB[noLocation])} -> 16-1-098 | H37: Building 16 | I37: {=_xlfn.XLOOKUP($B37, DB[samplingPoint], DB[location])} -> CIP/SIP | J37: {=_xlfn.XLOOKUP($B37, DB[samplingPoint], DB[waterType])} -> WFI | K37: =$A37+1 -> 46189 | L37: 46192 | M37: 0 | N37: =iferror(ROUNDUP(AVERAGE($M37), 0),"") -> 0 | R37: =iferror(ifs($N37>Q37, "NOT-PASSED", N37<=Q37, "PASSED"), "NA") -> PASSED | S37: FALSE | U37: synced
A38: 46188 | B38: WFI08 | C38: {=_xlfn.XLOOKUP(B38, DB[samplingPoint], DB[samplingTag])} -> SV216.04 | D38: PQ3-Day1 | E38: WP-26-0090 | F38: TRUE | G38: {=_xlfn.XLOOKUP($B38, DB[samplingPoint], DB[noLocation])} -> 16-1-098 | H38: Building 16 | I38: {=_xlfn.XLOOKUP($B38, DB[samplingPoint], DB[location])} -> CIP/SIP | J38: {=_xlfn.XLOOKUP($B38, DB[samplingPoint], DB[waterType])} -> WFI | K38: =$A38+1 -> 46189 | L38: 46192 | M38: 0 | N38: =iferror(ROUNDUP(AVERAGE($M38), 0),"") -> 0 | R38: =iferror(ifs($N38>Q38, "NOT-PASSED", N38<=Q38, "PASSED"), "NA") -> PASSED | S38: FALSE | U38: synced
A39: 46189 | B39: WFI03 | C39: {=_xlfn.XLOOKUP(B39, DB[samplingPoint], DB[samplingTag])} -> SV216.03 | D39: PQ3-Day2 | E39: WP-26-0091 | F39: TRUE | G39: {=_xlfn.XLOOKUP($B39, DB[samplingPoint], DB[noLocation])} -> 16-1-096 | H39: Building 16 | I39: {=_xlfn.XLOOKUP($B39, DB[samplingPoint], DB[location])} -> WASHING/TUNNEL-02 | J39: {=_xlfn.XLOOKUP($B39, DB[samplingPoint], DB[waterType])} -> WFI | K39: =$A39+2 -> 46191 | L39: 46195 | M39: 0 | N39: =iferror(ROUNDUP(AVERAGE($M39), 0),"") -> 0 | R39: =iferror(ifs($N39>Q39, "NOT-PASSED", N39<=Q39, "PASSED"), "NA") -> PASSED | S39: FALSE | U39: synced
A40: 46189 | B40: WFI04 | C40: {=_xlfn.XLOOKUP(B40, DB[samplingPoint], DB[samplingTag])} -> POU HE216.03 | D40: PQ3-Day2 | E40: WP-26-0091 | F40: TRUE | G40: {=_xlfn.XLOOKUP($B40, DB[samplingPoint], DB[noLocation])} -> 16-1-082 | H40: Building 16 | I40: {=_xlfn.XLOOKUP($B40, DB[samplingPoint], DB[location])} -> WASHING | J40: {=_xlfn.XLOOKUP($B40, DB[samplingPoint], DB[waterType])} -> WFI | K40: =$A40+2 -> 46191 | L40: 46195 | M40: 0 | N40: =iferror(ROUNDUP(AVERAGE($M40), 0),"") -> 0 | R40: =iferror(ifs($N40>Q40, "NOT-PASSED", N40<=Q40, "PASSED"), "NA") -> PASSED | S40: FALSE | U40: synced
...

Sheet _rpp2_registry
A1: worksheetNo | B1: rpp2Sheet | C1: sourceSheet | D1: updatedAt
A2: WT-26-0073 | B2: records_pw_prw | C2: prw-pw | D2: 2026-06-10T01:27:43.887Z
A3: WT-26-0074 | B3: records_pw_prw | C3: prw-pw | D3: 2026-07-10T09:03:33.159Z
A4: WT-26-0075 | B4: records_pw_prw | C4: prw-pw | D4: 2026-07-10T09:03:37.983Z
A5: WT-26-0076 | B5: records_pw_prw | C5: prw-pw | D5: 2026-06-10T06:41:12.687Z
A6: WT-26-0077 | B6: records_pw_prw | C6: prw-pw | D6: 2026-08-07T01:39:51.882Z
A7: WT-26-0078 | B7: records_pw_prw | C7: prw-pw | D7: 2026-06-10T06:41:19.852Z
A8: WT-26-0079 | B8: records_pw_prw | C8: prw-pw | D8: 2026-06-10T06:41:23.742Z
A9: WT-26-0080 | B9: records_pw_prw | C9: prw-pw | D9: 2026-06-11T03:43:51.141Z
A10: WT-26-0081 | B10: records_pw_prw | C10: prw-pw | D10: 2026-07-10T09:03:42.399Z
A11: WT-26-0070 | B11: records_pw_prw | C11: prw-pw | D11: 2026-07-10T09:03:27.694Z
A12: WT-26-0071 | B12: records_pw_prw | C12: prw-pw | D12: 2026-06-09T08:57:15.207Z
... A137: WP-26-0141 | B137: records_wfi | C137: wfi-pus | D137: 2026-09-03T02:24:29.003Z

Sheet Backup prw-pw
A1: samplingDate | B1: samplingPoint | C1: samplingTag | D1: recordStatus | E1: worksheetCreate | F1: noLocation | G1: building | H1: location | I1: waterType | J1: performedDate | K1: determinedDate | L1: result1 | M1: result2 | N1: resultAvg | O1: comment | P1: criteria | Q1: statusResult | R1: Exclude | S1: worksheet No. | T1: status | U1: syncStatus
A2: 46028 | B2: OLD29 | C2: {=_xlfn.XLOOKUP(B2, DB[samplingPoint], DB[samplingTag])} -> DV136.05 | D2: PQ3-Week1 | E2: TRUE | F2: {=_xlfn.XLOOKUP($B2, DB[samplingPoint], DB[noLocation])} -> 12-3-037 | G2: {=_xlfn.XLOOKUP($B2, DB[samplingPoint], DB[building])} -> Building 12 | H2: {=_xlfn.XLOOKUP($B2, DB[samplingPoint], DB[location])} -> GLASSWARE WASHING 1 | I2: {=_xlfn.XLOOKUP($B2, DB[samplingPoint], DB[waterType])} -> PW | J2: =$A2+1 -> 46029 | K2: 46032 | L2: 0 | M2: 0 | N2: =ROUNDUP(AVERAGE($L2:$M2), 0) -> 0 | O2: NA | P2: {=_xlfn.XLOOKUP($B2, DB[samplingPoint], DB[Criteria])} -> 100 | Q2: =iferror(ifs($N2>P2, "NOT-PASSED", N2<=P2, "PASSED"), "NA") -> PASSED | R2: FALSE | S2: WT-26-0001 | T2: {=if(S2:S854="", "pending", "complete")} -> complete | U2: pending
A3: 46028 | B3: OLD30 | C3: {=_xlfn.XLOOKUP(B3, DB[samplingPoint], DB[samplingTag])} -> DV136.06 | D3: PQ3-Week1 | E3: TRUE | F3: {=_xlfn.XLOOKUP($B3, DB[samplingPoint], DB[noLocation])} -> 12-3-037 | G3: {=_xlfn.XLOOKUP($B3, DB[samplingPoint], DB[building])} -> Building 12 | H3: {=_xlfn.XLOOKUP($B3, DB[samplingPoint], DB[location])} -> GLASSWARE WASHING 1 | I3: {=_xlfn.XLOOKUP($B3, DB[samplingPoint], DB[waterType])} -> PW | J3: =$A3+1 -> 46029 | K3: 46032 | L3: 0 | M3: 0 | N3: =ROUNDUP(AVERAGE($L3:$M3), 0) -> 0 | O3: NA | P3: {=_xlfn.XLOOKUP($B3, DB[samplingPoint], DB[Criteria])} -> 100 | Q3: =iferror(ifs($N3>P3, "NOT-PASSED", N3<=P3, "PASSED"), "NA") -> PASSED | R3: FALSE | S3: WT-26-0001 | T3: complete | U3: pending
A4: 46028 | B4: OLD26 | C4: {=_xlfn.XLOOKUP(B4, DB[samplingPoint], DB[samplingTag])} -> DV136.10 | D4: PQ3-Week1 | E4: TRUE | F4: {=_xlfn.XLOOKUP($B4, DB[samplingPoint], DB[noLocation])} -> 12-3-056 | G4: {=_xlfn.XLOOKUP($B4, DB[samplingPoint], DB[building])} -> Building 12 | H4: {=_xlfn.XLOOKUP($B4, DB[samplingPoint], DB[location])} -> MEDIA PREPARATION | I4: {=_xlfn.XLOOKUP($B4, DB[samplingPoint], DB[waterType])} -> PW | J4: =$A4+1 -> 46029 | K4: 46032 | L4: 0 | M4: 0 | N4: =ROUNDUP(AVERAGE($L4:$M4), 0) -> 0 | O4: NA | P4: {=_xlfn.XLOOKUP($B4, DB[samplingPoint], DB[Criteria])} -> 100 | Q4: =iferror(ifs($N4>P4, "NOT-PASSED", N4<=P4, "PASSED"), "NA") -> PASSED | R4: FALSE | S4: WT-26-0001 | T4: complete | U4: pending
A5: 46028 | B5: OLD24 | C5: {=_xlfn.XLOOKUP(B5, DB[samplingPoint], DB[samplingTag])} -> DV136.11 | D5: PQ3-Week1 | E5: TRUE | F5: {=_xlfn.XLOOKUP($B5, DB[samplingPoint], DB[noLocation])} -> 12-3-059 | G5: {=_xlfn.XLOOKUP($B5, DB[samplingPoint], DB[building])} -> Building 12 | H5: {=_xlfn.XLOOKUP($B5, DB[samplingPoint], DB[location])} -> AUTOCLAVE | I5: {=_xlfn.XLOOKUP($B5, DB[samplingPoint], DB[waterType])} -> PW | J5: =$A5+1 -> 46029 | K5: 46032 | L5: 0 | M5: 0 | N5: =ROUNDUP(AVERAGE($L5:$M5), 0) -> 0 | O5: NA | P5: {=_xlfn.XLOOKUP($B5, DB[samplingPoint], DB[Criteria])} -> 100 | Q5: =iferror(ifs($N5>P5, "NOT-PASSED", N5<=P5, "PASSED"), "NA") -> PASSED | R5: FALSE | S5: WT-26-0001 | T5: complete | U5: pending
A6: 46028 | B6: OLD25 | C6: {=_xlfn.XLOOKUP(B6, DB[samplingPoint], DB[samplingTag])} -> DV136.12 | D6: PQ3-Week1 | E6: TRUE | F6: {=_xlfn.XLOOKUP($B6, DB[samplingPoint], DB[noLocation])} -> 12-3-056 | G6: {=_xlfn.XLOOKUP($B6, DB[samplingPoint], DB[building])} -> Building 12 | H6: {=_xlfn.XLOOKUP($B6, DB[samplingPoint], DB[location])} -> MEDIA PREPARATION | I6: {=_xlfn.XLOOKUP($B6, DB[samplingPoint], DB[waterType])} -> PW | J6: =$A6+1 -> 46029 | K6: 46032 | L6: 0 | M6: 0 | N6: =ROUNDUP(AVERAGE($L6:$M6), 0) -> 0 | O6: NA | P6: {=_xlfn.XLOOKUP($B6, DB[samplingPoint], DB[Criteria])} -> 100 | Q6: =iferror(ifs($N6>P6, "NOT-PASSED", N6<=P6, "PASSED"), "NA") -> PASSED | R6: FALSE | S6: WT-26-0001 | T6: complete | U6: pending
A7: 46028 | B7: OLD22 | C7: {=_xlfn.XLOOKUP(B7, DB[samplingPoint], DB[samplingTag])} -> DV136.13 | D7: PQ3-Week1 | E7: TRUE | F7: {=_xlfn.XLOOKUP($B7, DB[samplingPoint], DB[noLocation])} -> 12-3-057 | G7: {=_xlfn.XLOOKUP($B7, DB[samplingPoint], DB[building])} -> Building 12 | H7: {=_xlfn.XLOOKUP($B7, DB[samplingPoint], DB[location])} -> STERILIZATION | I7: {=_xlfn.XLOOKUP($B7, DB[samplingPoint], DB[waterType])} -> PW | J7: =$A7+1 -> 46029 | K7: 46032 | L7: 0 | M7: 0 | N7: =ROUNDUP(AVERAGE($L7:$M7), 0) -> 0 | O7: NA | P7: {=_xlfn.XLOOKUP($B7, DB[samplingPoint], DB[Criteria])} -> 100 | Q7: =iferror(ifs($N7>P7, "NOT-PASSED", N7<=P7, "PASSED"), "NA") -> PASSED | R7: FALSE | S7: WT-26-0001 | T7: complete | U7: pending
A8: 46028 | B8: OLD27 | C8: {=_xlfn.XLOOKUP(B8, DB[samplingPoint], DB[samplingTag])} -> DV136.14 | D8: PQ3-Week1 | E8: TRUE | F8: {=_xlfn.XLOOKUP($B8, DB[samplingPoint], DB[noLocation])} -> 12-3-074 | G8: {=_xlfn.XLOOKUP($B8, DB[samplingPoint], DB[building])} -> Building 12 | H8: {=_xlfn.XLOOKUP($B8, DB[samplingPoint], DB[location])} -> DECONTAMINATION | I8: {=_xlfn.XLOOKUP($B8, DB[samplingPoint], DB[waterType])} -> PW | J8: =$A8+1 -> 46029 | K8: 46032 | L8: 0 | M8: 0 | N8: =ROUNDUP(AVERAGE($L8:$M8), 0) -> 0 | O8: NA | P8: {=_xlfn.XLOOKUP($B8, DB[samplingPoint], DB[Criteria])} -> 100 | Q8: =iferror(ifs($N8>P8, "NOT-PASSED", N8<=P8, "PASSED"), "NA") -> PASSED | R8: FALSE | S8: WT-26-0001 | T8: complete | U8: pending
A9: 46028 | B9: OLD21 | C9: {=_xlfn.XLOOKUP(B9, DB[samplingPoint], DB[samplingTag])} -> DV136.15 | D9: PQ3-Week1 | E9: TRUE | F9: {=_xlfn.XLOOKUP($B9, DB[samplingPoint], DB[noLocation])} -> 12-3-078 | G9: {=_xlfn.XLOOKUP($B9, DB[samplingPoint], DB[building])} -> Building 12 | H9: {=_xlfn.XLOOKUP($B9, DB[samplingPoint], DB[location])} -> GLASSWARE WASHING 2 | I9: {=_xlfn.XLOOKUP($B9, DB[samplingPoint], DB[waterType])} -> PW | J9: =$A9+1 -> 46029 | K9: 46032 | L9: 0 | M9: 0 | N9: =ROUNDUP(AVERAGE($L9:$M9), 0) -> 0 | O9: NA | P9: {=_xlfn.XLOOKUP($B9, DB[samplingPoint], DB[Criteria])} -> 100 | Q9: =iferror(ifs($N9>P9, "NOT-PASSED", N9<=P9, "PASSED"), "NA") -> PASSED | R9: FALSE | S9: WT-26-0001 | T9: complete | U9: pending
